Workbook

Sheet Start
A1: VitaSync – Coding-Backlog
A2: Arbeitsgrundlage für sieben Teammitglieder sowie einzeln beauftragte Claude-/Codex-Läufe. Stand: 14.10.2026.
A3: Bereich | B3: Anwendung | C3: Anzahl
A4: Umfang | B4: User Stories U001–U033 und die in der Spalte Anzahl gezaehlten Tasks, einschliesslich 18 Grundlagen. Nach D08 (kein Medizinprodukt) sind 4 Stories mit 13 Tasks gestrichen und weitere umgebaut; nach D09 (EU-Datenschutz, AI Act) kamen F016–F018, T-U028-03 und U033 hinzu. Siehe Spalten „Zweckprüfung (D08)“ und „Änderung“. | C4: =COUNTIFS(Tasks!$A$4:$A$1000,"<>")
A5: Nicht erledigt | C5: =COUNTIFS(Tasks!$M$4:$M$1000,"<>Erledigt",Tasks!$M$4:$M$1000,"<>Gestrichen",Tasks!$A$4:$A$1000,"<>")
A6: Erledigte Tasks | C6: =COUNTIFS(Tasks!$M$4:$M$1000,"Erledigt")
A7: Startreihenfolge | B7: 1. Entscheidungen klären. 2. Grundlagen bauen. 3. Tasks nach Reihenfolge und Abhängigkeiten übernehmen. M1 zuerst; optionale Stories separat freigeben.
A8: Taskgröße | B8: Ein Task liefert einen begrenzten, prüfbaren Baustein. Ziel: meist eine kurze Arbeitssitzung; abhängig von Erfahrung und Codebasis. Dauert ein Task voraussichtlich über einen halben Arbeitstag, vor Beginn weiter teilen.
A9: Bewertung | B9: Komplexität 1–5; Gesamt = (Programmierung + Recherche) / 2. Task Points sind erste relative Schätzungen (2 oder 3), keine Stunden. Story-UP und Task Points nicht addieren.
A10: Vor dem Start | B10: Task muss frei, alle Voraussetzungen erfüllt und benötigte Entscheidungen bestätigt sein. Optionalen Umfang ausdrücklich auswählen. Status von Offen auf Bereit setzen; menschlichen Verantwortlichen eintragen.
A11: Claude-/Codex-Auftrag | B11: Bearbeite genau Task <ID>. Lies Tasks, das zugehörige Briefing, die User Story und bestätigte Entscheidungen. Prüfe Voraussetzungen und Ownership. Implementiere nur den beschriebenen Umfang im bestehenden Stack. Führe die genannten Tests aus. Dokumentiere Änderungen, Testresultate und offene Punkte im Pull Request. Bei fehlenden fachlichen Regeln: blockieren, nicht erfinden.
A12: Arbeitsregel | B12: Ein Bearbeiter pro Task. Nach Implementierung: Im Review. Eine andere Person prüft und integriert; im Testlauf (D10) übernimmt eine Person alle Rollen und das Review ist die eigene Durchsicht des Diffs vor dem Merge. Erst dann Erledigt. Statusquelle ist die Spalte Status im Blatt Tasks; der Pull Request ist der Nachweis, in dem die Zeile im selben Zug gepflegt wird (docs/Arbeitsablauf.md). GitHub Issues sind optional.
A13: Wichtige Grenzen | B13: Synthetische Demo-Daten, keine Diagnosegarantien, keine automatische medizinische Regelgenerierung. Fachlich offene Aufgaben sind Research-Aufträge; Code darf erst gegen freigegebene kleine Fälle entstehen.
A14: Quellenstand | B14: IP_Use_Cases_und_Tasks.xlsx, Version 4 vom 14.10.2026. Grundlage sind die 31 abgestimmten Story-Zuschnitte; technische Task-Zerlegung hier neu als Planungsvorschlag.
A15: Abhängigkeiten | B15: Reihenfolge ist topologisch sortiert, keine Aufwand-Priorität. Innerhalb einer Story sind Tasks konservativ nacheinander geplant. Unabhängige Aufgaben können parallel bearbeitet werden.
A16: MVP-Grenze | B16: Bei Datenabruf, Analyse und fachlichen Erklärungen startet die Implementierung mit einem vereinbarten Typ/Thema. Zusätzliche Messgrößen, Quellen und Szenarien erhalten vor Erweiterung eigene kleine Tasks.
A17: Zweckbestimmung | B17: VitaSync ist kein Medizinprodukt (D08): allgemeine Information, Anzeige eigener Daten, Berechnung ohne Bewertung, Dokumentation. Keine individuelle Bewertung, Diagnose, Dringlichkeitseinstufung, Therapie- oder Medikamentenempfehlung.
A18: Gestrichene Tasks | C18: =COUNTIFS(Tasks!$M$4:$M$1000,"Gestrichen")
A19: Modulspalte | B19: „Modul (Vorschlag)“ in Tasks nennt den Ordner im Repository. Vorschlag, beim Übernehmen prüfen. „(neu)“ = Ordner bei Start anlegen.

Sheet Userstories
A1: VitaSync – 31 User Stories
A2: Unveränderte Story-IDs und UP aus dem bisherigen Backlog. Task Points werden separat geschätzt und nicht zu UP addiert.
A3: ID | B3: Meilenstein | C3: User Story | D3: Beschreibung | E3: Programmierung | F3: Recherche | G3: Gesamt | H3: UP | I3: Einplanung | J3: Tasks | K3: Abgrenzung | L3: Zweckprüfung (D08) | M3: Änderung
A4: U001 | B4: M3 | C4: Notfallhinweis und allgemeine Zuständigkeiten | D4: Als Nutzer, der Beschwerden schildert, möchte ich bei bestimmten Warnzeichen-Stichworten sofort einen festen allgemeinen Notfallhinweis (112, 116117) sehen und allgemein erfahren, welche Stelle wofür zuständig ist. | E4: 4 | F4: 5 | G4: =(E4+F4)/2 | H4: 21 | I4: Kern | J4: =COUNTIFS(Tasks!$B$4:$B$1000,A4,Tasks!$M$4:$M$1000,"<>Gestrichen") | K4: Erweitert um Warnzeichen und Grenzen diagnostischer Antworten. Fachlich geprüfte Regeln; keine Garantie, jeden Notfall zu erkennen. Bisherige hohe Schätzung bleibt bestehen. | L4: Umgebaut | M4: Umgebaut nach D08: keine individuelle Dringlichkeitseinstufung, keine Triage. Fester, für alle gleicher Hinweistext aus geprüfter Quelle. Keine Garantie, jeden Notfall zu erkennen; nie Entwarnung.
A5: U002 | B5: M4 | C5: Symptome mit vermuteter Ursache | D5: Als Nutzer mit Beschwerden und einer vermuteten Ursache möchte ich meine Vermutung einordnen lassen, damit ich passende nächste Schritte verstehe. | E5: 4 | F5: 4 | G5: =(E5+F5)/2 | H5: 13 | I5: Gestrichen | J5: =COUNTIFS(Tasks!$B$4:$B$1000,A5,Tasks!$M$4:$M$1000,"<>Gestrichen") | K5: Kontext und persönliche Daten müssen kontrolliert kombiniert werden; fachliche Prüfung gegen vorschnelle Ursachenzuordnung. | L5: Gestrichen | M5: Ursachen einer Beschwerde einzuordnen ist Diagnostik.
A6: U003 | B6: M4 | C6: Unklarer Zusammenhang mehrerer Beschwerden | D6: Als Nutzer mit einem bekannten Ereignis und mehreren Beschwerden möchte ich klären, welche Angaben zusammengehören könnten und welche getrennt abgeklärt werden müssen. | E6: 5 | F6: 5 | G6: =(E6+F6)/2 | H6: 21 | I6: Gestrichen | J6: =COUNTIFS(Tasks!$B$4:$B$1000,A6,Tasks!$M$4:$M$1000,"<>Gestrichen") | K6: Mehrere Symptome, Ereignisse und Zeitbezüge sowie mehrdeutige Beziehungen; besonders hoher fachlicher Recherche- und Prüfaufwand. | L6: Gestrichen | M6: Zusammenhänge mehrerer Beschwerden zu klären ist Differenzialdiagnostik.
A7: U004 | B7: M1 | C7: Gesundheitsfremde Frage abweisen | D7: Als Nutzer mit einer gesundheitsfremden Frage möchte ich eine kurze Erklärung des Aufgabenbereichs erhalten, damit ich weiß, wofür der Chatbot zuständig ist. | E7: 1 | F7: 1 | G7: =(E7+F7)/2 | H7: 3 | I7: Kern | J7: =COUNTIFS(Tasks!$B$4:$B$1000,A7,Tasks!$M$4:$M$1000,"<>Gestrichen") | K7: Einfacher Intent und feste Antwort; wenig Recherche, sofern das Labelset bereits vereinbart ist. | L7: Erlaubt
A8: U005 | B8: M2 | C8: Unzulässige Datenabfrage verhindern | D8: Als berechtigter Nutzer möchte ich, dass unzulässige Abfragen und Zugriffe auf fremde Daten blockiert werden, damit meine Gesundheitsdaten geschützt bleiben. | E8: 5 | F8: 4 | G8: =(E8+F8)/2 | H8: 13 | I8: Kern | J8: =COUNTIFS(Tasks!$B$4:$B$1000,A8,Tasks!$M$4:$M$1000,"<>Gestrichen") | K8: Berechtigungen, Sitzungsisolation und Angriffstests über mehrere Komponenten; zusätzlicher Datenschutz- und Sicherheitsklärungsbedarf. | L8: Erlaubt
A9: U006 | B9: M4 | C9: Eigene Daten analysieren lassen | D9: Als Nutzer möchte ich meine eigenen Gesundheits- und Alltagsdaten zwischen gewählten Zeiträumen vergleichen und verständlich erklärt bekommen. Verwendete Werte, Einheiten, Zeitpunkte und Quellen sowie fehlende Daten sollen sichtbar sein. | E9: 4 | F9: 4 | G9: =(E9+F9)/2 | H9: 13 | I9: Kern | J9: =COUNTIFS(Tasks!$B$4:$B$1000,A9,Tasks!$M$4:$M$1000,"<>Gestrichen") | K9: Zeitraumvergleich war enthalten. Präzisiert um Transparenz und individuelle Werteerklärung; Referenzbereiche nur aus geeigneter Quelle und mit Kontext, keine Diagnose. | L9: Umgebaut | M9: Umgebaut nach D08: Zeitraumvergleich, Kennzahlen, Datenlücken und Quellen ja. Keine Referenzbereiche, keine Bewertung als normal/auffällig, keine Diagnose.
A10: U007 | B10: M2 | C10: Eigene Daten unverändert abrufen | D10: Als Nutzer möchte ich meine eigenen vorhandenen Daten gezielt mit Wert, Einheit, Zeitpunkt und Quelle anzeigen lassen, damit ich ihre Herkunft ohne zusätzliche Interpretation nachvollziehen kann. | E10: 3 | F10: 2 | G10: =(E10+F10)/2 | H10: 8 | I10: Kern | J10: =COUNTIFS(Tasks!$B$4:$B$1000,A10,Tasks!$M$4:$M$1000,"<>Gestrichen") | K10: Quellennachweis ist Teil des Datenabrufs; keine doppelte Transparenz-Story erforderlich. | L10: Erlaubt
A11: U008 | B11: M4 | C11: Allgemeine Vorsorge-Information | D11: Als Nutzer möchte ich allgemeine Informationen zu Vorsorgeangeboten (z. B. Check-up) erhalten, damit ich mich informiert an meine Arztpraxis wenden kann. | E11: 4 | F11: 5 | G11: =(E11+F11)/2 | H11: 21 | I11: Kern | J11: =COUNTIFS(Tasks!$B$4:$B$1000,A11,Tasks!$M$4:$M$1000,"<>Gestrichen") | K11: Hoher Leitlinien- und Aktualitätsaufwand; Unterscheidung von Vorsorge, Beschwerden und diagnostischer Abklärung. | L11: Umgebaut | M11: Umgebaut nach D08: nur allgemeine Information, keine individuelle Aussage, was eine Person abklären lassen sollte.
A12: U009 | B12: M1 | C12: Allgemeine Gesundheitsinformation erklären | D12: Als Nutzer möchte ich allgemeine Gesundheitsfragen und Zusammenhänge mit Lebensgewohnheiten kurz und verständlich erklärt bekommen. Verwendete Fachbegriffe werden erläutert; Quellen, Grenzen und bei Bedarf nächste Schritte sind erkennbar, damit ich mich besser orientieren kann. | E12: 2 | F12: 3 | G12: =(E12+F12)/2 | H12: 5 | I12: Kern | J12: =COUNTIFS(Tasks!$B$4:$B$1000,A12,Tasks!$M$4:$M$1000,"<>Gestrichen") | K12: U009 bündelt allgemeine Fragen, Lifestyle-Grundlagen sowie kurze, verständliche Antworten mit erklärten Fachbegriffen. Persönliche Datenanalysen gehören zu U006; ausführliche Details auf Nachfrage. UP bleiben 5, da Antwortqualität zum bisherigen Umfang gehört. | L12: Erlaubt
A13: U010 | B13: M1 | C13: Unvollständige Anfrage gezielt klären | D13: Als Nutzer mit einer unklaren oder unvollständigen Anfrage möchte ich eine gezielte Rückfrage erhalten, damit mein Anliegen richtig verstanden wird. | E13: 3 | F13: 3 | G13: =(E13+F13)/2 | H13: 8 | I13: Kern | J13: =COUNTIFS(Tasks!$B$4:$B$1000,A13,Tasks!$M$4:$M$1000,"<>Gestrichen") | K13: Zustandsverwaltung und sinnvolle Rückfrageauswahl mit fachlicher Abstimmung. | L13: Erlaubt
A14: U011 | B14: M2 | C14: Fehlende oder veraltete Daten erkennen | D14: Als Nutzer möchte ich erfahren, wenn Daten fehlen, veraltet oder technisch nicht verfügbar sind, damit ich die Grenzen einer Anzeige oder Analyse verstehe. | E14: 3 | F14: 2 | G14: =(E14+F14)/2 | H14: 5 | I14: Kern | J14: =COUNTIFS(Tasks!$B$4:$B$1000,A14,Tasks!$M$4:$M$1000,"<>Gestrichen") | K14: Datenzustände und Fehlermeldungen sind gut eingrenzbar; Definition von Aktualität verlangt etwas Recherche. | L14: Erlaubt
A15: U012 | B15: M3 | C15: Eigene Angaben im Dialog korrigieren | D15: Als Nutzer möchte ich eine falsch verstandene Angabe korrigieren können, damit die weitere Antwort auf dem richtigen Gesprächskontext beruht. | E15: 3 | F15: 2 | G15: =(E15+F15)/2 | H15: 5 | I15: Kern | J15: =COUNTIFS(Tasks!$B$4:$B$1000,A15,Tasks!$M$4:$M$1000,"<>Gestrichen") | K15: Gezielte Zustandsänderung und erneutes Routing; wenig externe Recherche, aber klare Regeln für Datenherkunft. | L15: Erlaubt
A16: U013 | B16: M3 | C16: Mehrere Anliegen in einer Nachricht trennen | D16: Als Nutzer mit mehreren Anliegen möchte ich, dass der Chatbot die Anliegen getrennt behandelt und erkannte dringliche Warnzeichen priorisiert, damit eine Notfallinformation nicht durch andere Fragen verzögert wird. | E16: 4 | F16: 2 | G16: =(E16+F16)/2 | H16: 8 | I16: Kern | J16: =COUNTIFS(Tasks!$B$4:$B$1000,A16,Tasks!$M$4:$M$1000,"<>Gestrichen") | K16: Mehrfachanliegen bleiben der Schwerpunkt. Warnzeichen haben Vorrang; Zusammenspiel mit U001 fachlich prüfen. | L16: Umgebaut | M16: Umgebaut nach D08: Mehrfachanliegen trennen. Enthält ein Anliegen ein Warnzeichen-Stichwort, steht der feste Notfallhinweis aus U001 zuerst. Keine Dringlichkeitsrangfolge.
A17: U014 | B17: M3 | C17: Arztzusammenfassung als PDF | D17: Als Nutzer möchte ich eine Vorschau meiner berichteten Beschwerden, ihrer Dauer und ausgewählter eigener Daten prüfen und als PDF herunterladen, damit ich diese beim Arzttermin strukturiert vorlegen kann. | E17: 3 | F17: 3 | G17: =(E17+F17)/2 | H17: 8 | I17: Ergänzung | J17: =COUNTIFS(Tasks!$B$4:$B$1000,A17,Tasks!$M$4:$M$1000,"<>Gestrichen") | K17: Zwei Vorschläge zusammengeführt. M3 statt M2, da strukturierter Symptomdialog benötigt wird. Selbstauskunft, Datenquellen und Chatbot-Hinweise unterscheiden; keine Diagnose oder automatische Übermittlung. | L17: Umgebaut | M17: Umgebaut nach D08: nur Selbstauskunft und eigene Daten mit Quelle. Keine Chatbot-Einschätzung im PDF, keine automatische Übermittlung.
A18: U015 | B18: M3 | C18: Antworten bewerten | D18: Als Nutzer möchte ich Antworten positiv oder negativ bewerten und optional begründen, damit das Projektteam Fehler untersuchen und Verbesserungen gezielt prüfen kann. | E18: 2 | F18: 2 | G18: =(E18+F18)/2 | H18: 5 | I18: Ergänzung | J18: =COUNTIFS(Tasks!$B$4:$B$1000,A18,Tasks!$M$4:$M$1000,"<>Gestrichen") | K18: Feedback wird gesammelt und geprüft. Es löst weder automatisches Training noch ungeprüfte Promptänderungen aus; nur erforderlichen Kontext speichern. | L18: Erlaubt
A19: U016 | B19: M4 | C19: An Datenaktualisierung erinnern | D19: Als Nutzer möchte ich freiwillige Erinnerungen für selbst gewählte Messdaten aktivieren, ändern und abschalten können, damit ich fehlende oder ältere Angaben bei Bedarf ergänze. | E19: 3 | F19: 3 | G19: =(E19+F19)/2 | H19: 8 | I19: Optional | J19: =COUNTIFS(Tasks!$B$4:$B$1000,A19,Tasks!$M$4:$M$1000,"<>Gestrichen") | K19: Zunächst Erinnerungen innerhalb der App. Push, E-Mail und medizinisch festgelegte Messintervalle sind nicht enthalten. Aktualität garantiert keine präzise Diagnose. | L19: Erlaubt
A20: U017 | B20: M1 | C20: Deutsch und Englisch wählen | D20: Als Nutzer möchte ich Deutsch oder Englisch für Eingaben und Antworten wählen können, damit ich die unterstützten Funktionen in einer verständlichen Sprache nutzen kann. | E20: 3 | F20: 4 | G20: =(E20+F20)/2 | H20: 8 | I20: Kern | J20: =COUNTIFS(Tasks!$B$4:$B$1000,A20,Tasks!$M$4:$M$1000,"<>Gestrichen") | K20: Zusätzlich zur deutschsprachigen Basis. Rückfragen, Fehlermeldungen und fachliche Texte in beiden Sprachen prüfen; keine unbegrenzte Sprachunterstützung oder Sicherheitsgarantie. | L20: Erlaubt | M20: Entscheidung DE/EN 14.10.2026
A21: U018 | B21: M4 | C21: Medikamente als Kontext angeben | D21: Als Nutzer möchte ich aktuell eingenommene Medikamente als Selbstauskunft angeben können, damit diese bei Rückfragen und der Vorbereitung einer ärztlichen oder pharmazeutischen Abklärung berücksichtigt werden. | E21: 4 | F21: 5 | G21: =(E21+F21)/2 | H21: 13 | I21: Gestrichen | J21: =COUNTIFS(Tasks!$B$4:$B$1000,A21,Tasks!$M$4:$M$1000,"<>Gestrichen") | K21: Eingabe bestätigt nicht die Richtigkeit der Medikation. Keine automatische Wechselwirkungsprüfung, Therapieänderung oder Kausaldiagnose. Dafür wären zusätzliche geeignete Arzneimittelquellen und fachliche Validierung nötig. | L21: Gestrichen | M21: Medikation als Kontext ohne Auswertung bringt keinen Nutzen; Auswertung wäre Medizinprodukt-Funktion.
A22: U019 | B22: M2 | C22: Eigenes Gesundheitsprofil pflegen | D22: Als Nutzer möchte ich ausgewählte Angaben wie Allergien, Vorerkrankungen und relevante Vorgeschichte in meinem Profil ansehen und als Selbstauskunft ergänzen oder korrigieren, damit der freigegebene Kontext berücksichtigt werden kann. | E22: 4 | F22: 3 | G22: =(E22+F22)/2 | H22: 13 | I22: Optional | J22: =COUNTIFS(Tasks!$B$4:$B$1000,A22,Tasks!$M$4:$M$1000,"<>Gestrichen") | K22: Erweitert den bisherigen lesenden Umfang: eigene Angaben getrennt von importierten Befunden speichern. Keine ungeprüfte Änderung fremder FHIR-Daten; Herkunft und Aktualität kennzeichnen. | L22: Umgebaut | M22: Umgebaut nach D08: Profil wird gespeichert, angezeigt und für das PDF genutzt, aber nicht zur Bewertung von Werten oder Beschwerden.
A23: U020 | B23: M4 | C23: Symptome im Verlauf dokumentieren | D23: Als Nutzer möchte ich Beschwerden mit Zeitpunkt, Dauer und selbst eingeschätzter Stärke erfassen und im Verlauf ansehen, damit ich Veränderungen nachvollziehen und beim Arzttermin beschreiben kann. | E23: 4 | F23: 3 | G23: =(E23+F23)/2 | H23: 13 | I23: Optional | J23: =COUNTIFS(Tasks!$B$4:$B$1000,A23,Tasks!$M$4:$M$1000,"<>Gestrichen") | K23: Neue dauerhafte Speicherung und Verlaufseingabe, daher eigenständig neben U006. Korrektur und Löschung vorsehen; ein Verlauf belegt keine Ursache. | L23: Erlaubt
A24: U021 | B24: M3 | C24: Widersprüchliche Angaben klären | D24: Als Nutzer möchte ich bei widersprüchlichen Angaben zu Zeitpunkt, Wert, Person oder Selbstauskunft gezielt gefragt werden, damit bestätigte und weiterhin unklare Informationen unterscheidbar bleiben. | E24: 4 | F24: 3 | G24: =(E24+F24)/2 | H24: 8 | I24: Ergänzung | J24: =COUNTIFS(Tasks!$B$4:$B$1000,A24,Tasks!$M$4:$M$1000,"<>Gestrichen") | K24: U010 behandelt fehlende Angaben, U012 aktive Nutzerkorrekturen. Diese Story ergänzt proaktive Konflikterkennung. Unterschiedliche Messzeiten sind nicht automatisch ein Widerspruch; Befunde nicht still überschreiben. | L24: Erlaubt
A25: U022 | B25: M2 | C25: Festgelegte FHIR-JSON-Daten importieren | D25: Als Nutzer möchte ich eigene Daten aus einer unterstützten FHIR-JSON-Datei importieren und vor Übernahme prüfen können, damit weitere Daten mit nachvollziehbarer Herkunft verfügbar werden. | E25: 4 | F25: 4 | G25: =(E25+F25)/2 | H25: 13 | I25: Optional | J25: =COUNTIFS(Tasks!$B$4:$B$1000,A25,Tasks!$M$4:$M$1000,"<>Gestrichen") | K25: Für den Prototyp nur synthetische Dateien, vereinbarte FHIR-Version und Ressourcen. Größen-, Struktur-, Patienten- und Dublettenprüfung. Kein beliebiges JSON-Mapping, PDF/OCR oder automatischer Wearable-Liveimport. 13 UP statt vorgeschlagener 8 wegen Importvalidierung und Speicherung. | L25: Erlaubt
A26: U023 | B26: M2 | C26: Datennutzung je Quelle steuern | D26: Als Nutzer möchte ich sehen, welche Datenquellen für welchen Zweck genutzt werden, und eine darauf beruhende Freigabe erteilen oder widerrufen können, damit ich die weitere Nutzung kontrollieren kann. | E26: 4 | F26: 5 | G26: =(E26+F26)/2 | H26: 13 | I26: Voraussetzung für Speicherung | J26: =COUNTIFS(Tasks!$B$4:$B$1000,A26,Tasks!$M$4:$M$1000,"<>Gestrichen") | K26: Aus Sammelstory getrennt. Widerruf sperrt die betreffende weitere Verarbeitung; er ist nicht dasselbe wie Löschung. Rechtsgrundlage, Zwecke und Projektumfang mit Betreuung/Datenschutz klären. Keine pauschale Zusage der DSGVO-Konformität. | L26: Erlaubt
A27: U024 | B27: M2 | C27: Gespeicherte eigene Daten löschen | D27: Als Nutzer möchte ich meine in der Anwendung gespeicherten Chats, Selbstauskünfte und importierten Daten auswählen und deren Löschung bestätigen können, damit ich die gespeicherten Informationen kontrollieren kann. | E27: 4 | F27: 4 | G27: =(E27+F27)/2 | H27: 13 | I27: Voraussetzung für Speicherung | J27: =COUNTIFS(Tasks!$B$4:$B$1000,A27,Tasks!$M$4:$M$1000,"<>Gestrichen") | K27: Aus Sammelstory getrennt. Umfang, Fristen, Protokolle und Sicherungskopien klären. Keine Zusage, fremde Originalakten oder alle externen Kopien sofort und ausnahmslos löschen zu können. | L27: Erlaubt
A28: U025 | B28: M3 | C28: Gesprächskontext innerhalb eines Chats | D28: Als Nutzer möchte ich, dass bestätigte Angaben innerhalb meines aktuellen Chats berücksichtigt werden, damit ich mich bei Folgefragen nicht wiederholen muss. | E28: 3 | F28: 2 | G28: =(E28+F28)/2 | H28: 5 | I28: Kern | J28: =COUNTIFS(Tasks!$B$4:$B$1000,A28,Tasks!$M$4:$M$1000,"<>Gestrichen") | K28: Sitzungsgebundener Kontext, keine chatübergreifende Erinnerung. Neues Gespräch setzt Kontext zurück; begrenztes Kontextfenster und Korrekturen mit U012 abstimmen. | L28: Erlaubt
A29: U026 | B29: M1 | C29: Bearbeitungsstatus und Fehler erkennen | D29: Als Nutzer möchte ich nach dem Absenden einen Bearbeitungsstatus sehen und bei Zeitüberschreitung eine verständliche Fehlermeldung mit Wiederholungsmöglichkeit erhalten, damit ich weiß, ob meine Anfrage bearbeitet wird. | E29: 2 | F29: 1 | G29: =(E29+F29)/2 | H29: 3 | I29: Kern | J29: =COUNTIFS(Tasks!$B$4:$B$1000,A29,Tasks!$M$4:$M$1000,"<>Gestrichen") | K29: Nutzerziel ergänzt E002/E003, keine zweite Task-Schätzung. Timeout konfigurierbar; keine feste Antwortzeit ohne Messung versprechen. | L29: Erlaubt
A30: U027 | B30: M1 | C30: Chat-Verarbeitung freigeben oder ablehnen | D30: Als Nutzer möchte ich vor der Verarbeitung meiner gesundheitsbezogenen Eingabe ausdrücklich zustimmen, ablehnen oder meine Zustimmung später widerrufen können, damit ich die weitere Chat-Verarbeitung kontrolliere. | E30: 3 | F30: 4 | G30: =(E30+F30)/2 | H30: 8 | I30: Kern | J30: =COUNTIFS(Tasks!$B$4:$B$1000,A30,Tasks!$M$4:$M$1000,"<>Gestrichen") | K30: M1: Chat-Einwilligung mit serverseitiger Prüfung vor Modellaufruf. U023 bleibt quellenbezogene Steuerung in M2; U024 bleibt Löschung. Prototyp mit synthetischen Daten, keine Rechtskonformitätszusage. | L30: Erlaubt
A31: U028 | B31: M1 | C31: KI und Grenzen sichtbar erkennen | D31: Als Nutzer möchte ich vor dem Chat erfahren, dass ich mit einer KI und keinem Arzt spreche, und die KI-Kennzeichnung dauerhaft sehen, damit ich die Herkunft und Grenzen der Antworten verstehe. | E31: 1 | F31: 2 | G31: =(E31+F31)/2 | H31: 2 | I31: Kern | J31: =COUNTIFS(Tasks!$B$4:$B$1000,A31,Tasks!$M$4:$M$1000,"<>Gestrichen") | K31: Versionierter Hinweis vor Zustimmung; dauerhafte Kennzeichnung im Header. Kein Ersatz für medizinische Versorgung. | L31: Erlaubt
A32: U029 | B32: M4 | C32: Bewegungsdaten und Trainingsziele besprechen | D32: Als Nutzer möchte ich meine freigegebenen Bewegungsdaten und Trainingsziele gemeinsam betrachten und allgemeine Hinweise dazu erhalten, damit ich Fragen für eine fachliche Trainingsberatung vorbereiten kann. | E32: 4 | F32: 5 | G32: =(E32+F32)/2 | H32: 13 | I32: Optional | J32: =COUNTIFS(Tasks!$B$4:$B$1000,A32,Tasks!$M$4:$M$1000,"<>Gestrichen") | K32: Aus Trainings-/Ernährungs-Epic getrennt. Keine sichere individuelle Belastungsfreigabe oder Garantie der Zielerreichung; bekannte Erkrankungen berücksichtigen. U006 liefert die Datenanalyse. | L32: Umgebaut | M32: Umgebaut nach D08: allgemeine Bewegungs- und Lifestyle-Information zu selbst gesetzten Zielen. Kein Bezug zu Erkrankungen, keine Belastungsfreigabe.
A33: U030 | B33: M4 | C33: Ernährungsdaten und Ziele besprechen | D33: Als Nutzer möchte ich meine freigegebenen Ernährungsangaben und Ziele verständlich eingeordnet bekommen, damit ich allgemeine Verbesserungsmöglichkeiten und Fragen für eine Ernährungsberatung erkenne. | E33: 4 | F33: 5 | G33: =(E33+F33)/2 | H33: 13 | I33: Optional | J33: =COUNTIFS(Tasks!$B$4:$B$1000,A33,Tasks!$M$4:$M$1000,"<>Gestrichen") | K33: Eigenständiger Daten- und Wissensbereich gegenüber Training. Keine therapeutischen Diätpläne, Dosierungen oder Erfolgsgarantien; Allergien und Vorerkrankungen als Kontext behandeln. | L33: Umgebaut | M33: Umgebaut nach D08: allgemeine Ernährungsinformation zu selbst gesetzten Zielen. Kein Bezug zu Erkrankungen, keine Diätpläne oder Dosierungen.
A34: U031 | B34: M4 | C34: Vorerkrankungen bei Abweichungen berücksichtigen | D34: Als Nutzer möchte ich, dass vorhandene Erkrankungen und bekannte Ausgangswerte bei der Einordnung auffälliger Daten berücksichtigt werden, ohne neue Warnzeichen zu übergehen, damit ich eine nachvollziehbare Einordnung erhalte. | E34: 4 | F34: 5 | G34: =(E34+F34)/2 | H34: 13 | I34: Gestrichen | J34: =COUNTIFS(Tasks!$B$4:$B$1000,A34,Tasks!$M$4:$M$1000,"<>Gestrichen") | K34: Nicht pauschal als normal einstufen. Neu auftretende oder veränderte Angaben separat prüfen, Unsicherheit benennen. Benötigt U006/U007 und die Versorgungsregeln aus M3. | L34: Gestrichen | M34: Auffällige Werte einer Person mit Vorerkrankungen einzuordnen ist Befundbewertung.
A35: U032 | B35: M4 | C35: Befunddokument auslesen | D35: Als Nutzer möchte ich ein Foto oder PDF eines eigenen Befunds hochladen und die ausgelesenen Werte prüfen und bestätigen, damit sie wie importierte Daten mit Herkunft verfügbar sind. | E35: 4 | F35: 3 | G35: =(E35+F35)/2 | H35: 13 | I35: Optional | J35: =COUNTIFS(Tasks!$B$4:$B$1000,A35,Tasks!$M$4:$M$1000,"<>Gestrichen") | K35: Neu (Vorschlag). Nur Abschreiben von Wert, Einheit und Datum; Bestätigung durch Nutzer ist Pflicht. Keine Bewertung, keine medizinischen Bilder (Haut, Röntgen, Wunden). Nur synthetische Befunde. Bildfähigkeit des Modells nach D03. | L35: Neu | M35: Optional für Datei- und Bildanalyse; nur Auslesen mit Bestätigung.
A36: U033 | B36: M2 | C36: Eigene Daten auskunft und exportieren | D36: Als Nutzer möchte ich sehen, welche Daten VitaSync über mich gespeichert hat, und sie in einem gängigen Format herunterladen, damit ich meine Rechte auf Auskunft und Datenübertragbarkeit nutzen kann. | E36: 2 | F36: 2 | G36: =(E36+F36)/2 | H36: 8 | I36: Kern | J36: =COUNTIFS(Tasks!$B$4:$B$1000,A36,Tasks!$M$4:$M$1000,"<>Gestrichen") | K36: Neu nach D09 (Art. 15 und 20 DSGVO). Export als JSON, Gesundheitsdaten wo möglich als FHIR. Nur eigene Daten. | L36: Neu | M36: Pflicht aus DSGVO; fehlte im Backlog.

Sheet Tasks
A1: VitaSync – ausführbare Arbeitspakete
A2: Nach Reihenfolge beginnen; Abhängigkeiten und Entscheidungen prüfen. Alle Tasks starten offen. Vollständige Arbeitsaufträge stehen unter Briefings.
A3: Task-ID | B3: Story-ID | C3: Meilenstein | D3: Reihenfolge | E3: Task | F3: Art | G3: Programmierung | H3: Recherche | I3: Gesamt | J3: Task Points | K3: Voraussetzungen | L3: Entscheidungen | M3: Status | N3: Verantwortlich | O3: Bearbeiter | P3: KI-Einsatz | Q3: Einplanung | R3: Modul (Vorschlag) | S3: Zweckprüfung (D08) | T3: Änderung
A4: F001 | B4: BASIS | C4: M1 | D4: 1 | E4: Entscheidungen und Schnittstellen abstimmen | F4: Research | G4: 1 | H4: 3 | I4: =(G4+H4)/2 | J4: 2 | L4: D01, D03 | M4: Erledigt | N4: Atakan | O4: Mensch | P4: Unterstützend | Q4: Kern | R4: docs/decisions | S4: Erlaubt
A5: F002 | B5: BASIS | C5: M1 | D5: 2 | E5: Projektstart reproduzierbar machen | F5: Code | G5: 2 | H5: 1 | I5: =(G5+H5)/2 | J5: 3 | K5: F001 | M5: Erledigt | N5: Atakan | O5: Claude | P5: Nach menschlicher Freigabe | Q5: Kern | R5: infra, apps | S5: Erlaubt | T5: PR #1 gemergt 14.10.2026
A6: F003 | B6: BASIS | C6: M1 | D6: 3 | E6: Chat-API-Vertrag festlegen | F6: Research | G6: 1 | H6: 3 | I6: =(G6+H6)/2 | J6: 2 | K6: F001 | M6: Erledigt | N6: Atakan | O6: Claude | P6: Unterstützend | Q6: Kern | R6: contracts/api | S6: Erlaubt | T6: PR #2 gemergt 14.10.2026
A7: F004 | B7: BASIS | C7: M1 | D7: 4 | E7: Testautomatisierung einrichten | F7: Code | G7: 2 | H7: 1 | I7: =(G7+H7)/2 | J7: 3 | K7: F002 | M7: Offen | P7: Nach menschlicher Freigabe | Q7: Kern | R7: .github, apps/*/tests | S7: Erlaubt
A8: F005 | B8: BASIS | C8: M1 | D8: 5 | E8: Chat-UX für Kernzustände skizzieren | F8: UX | G8: 1 | H8: 1 | I8: =(G8+H8)/2 | J8: 3 | K8: F003 | M8: Offen | P8: Unterstützend | Q8: Kern | R8: apps/web | S8: Erlaubt
A9: F006 | B9: BASIS | C9: M1 | D9: 6 | E9: Chatoberfläche mit Testantwort bauen | F9: Code | G9: 2 | H9: 1 | I9: =(G9+H9)/2 | J9: 3 | K9: F005, F002 | M9: Offen | P9: Nach menschlicher Freigabe | Q9: Kern | R9: apps/web | S9: Erlaubt | T9: F002 liefert nur apps/api und infra. Web-Grundgeruest (package.json, Vite, TypeScript) gehoert zu diesem Task.
A10: F007 | B10: BASIS | C10: M1 | D10: 7 | E10: Backend mit fester Antwort anbinden | F10: Code | G10: 2 | H10: 1 | I10: =(G10+H10)/2 | J10: 3 | K10: F003, F006 | M10: Offen | P10: Nach menschlicher Freigabe | Q10: Kern | R10: api, features/chat | S10: Erlaubt
A11: F008 | B11: BASIS | C11: M1 | D11: 8 | E11: Lokalen Modelladapter isolieren | F11: Code | G11: 2 | H11: 1 | I11: =(G11+H11)/2 | J11: 3 | K11: F007 | L11: D03 | M11: Offen | P11: Nach menschlicher Freigabe | Q11: Kern | R11: adapters/llm | S11: Erlaubt
A12: F009 | B12: BASIS | C12: M1 | D12: 9 | E12: Synthetische Testdaten und Loggrenzen festlegen | F12: Research | G12: 1 | H12: 3 | I12: =(G12+H12)/2 | J12: 2 | K12: F003 | L12: D05 | M12: Offen | P12: Unterstützend | Q12: Kern | R12: data/synthetic | S12: Erlaubt
A13: T-U004-01 | B13: U004 | C13: M1 | D13: 10 | E13: Routing-Beispiele festlegen | F13: Research | G13: 1 | H13: 3 | I13: =(G13+H13)/2 | J13: 2 | K13: F007, F008 | M13: Offen | P13: Unterstützend | Q13: Kern | R13: knowledge, evals | S13: Erlaubt
A14: T-U004-02 | B14: U004 | C14: M1 | D14: 11 | E14: Intent-Validator implementieren | F14: Code | G14: 2 | H14: 1 | I14: =(G14+H14)/2 | J14: 3 | K14: T-U004-01 | M14: Offen | P14: Nach menschlicher Freigabe | Q14: Kern | R14: features/recognition | S14: Erlaubt
A15: T-U004-03 | B15: U004 | C15: M1 | D15: 12 | E15: Fachfremde Anfrage beantworten | F15: Code | G15: 2 | H15: 1 | I15: =(G15+H15)/2 | J15: 3 | K15: T-U004-02 | M15: Offen | P15: Nach menschlicher Freigabe | Q15: Kern | R15: features/recognition | S15: Erlaubt
A16: T-U009-01 | B16: U009 | C16: M1 | D16: 13 | E16: Kleines Wissenspaket kuratieren | F16: Research | G16: 1 | H16: 3 | I16: =(G16+H16)/2 | J16: 2 | K16: F007, T-U004-03, F008 | L16: D04 | M16: Offen | P16: Unterstützend | Q16: Kern | R16: knowledge | S16: Erlaubt
A17: T-U009-02 | B17: U009 | C17: M1 | D17: 14 | E17: Wissenseintrag auswählen | F17: Code | G17: 2 | H17: 1 | I17: =(G17+H17)/2 | J17: 3 | K17: T-U009-01 | M17: Offen | P17: Nach menschlicher Freigabe | Q17: Kern | R17: features/guidance | S17: Erlaubt
A18: T-U009-03 | B18: U009 | C18: M1 | D18: 15 | E18: Verständliche Antwort formatieren | F18: Code | G18: 2 | H18: 1 | I18: =(G18+H18)/2 | J18: 3 | K18: T-U009-02 | M18: Offen | P18: Nach menschlicher Freigabe | Q18: Kern | R18: features/guidance | S18: Erlaubt
A19: T-U009-04 | B19: U009 | C19: M1 | D19: 16 | E19: Antwortdarstellung integrieren | F19: Code | G19: 2 | H19: 1 | I19: =(G19+H19)/2 | J19: 3 | K19: T-U009-03 | M19: Offen | P19: Nach menschlicher Freigabe | Q19: Kern | R19: apps/web | S19: Erlaubt
A20: T-U010-01 | B20: U010 | C20: M1 | D20: 17 | E20: Pflichtangaben für eine Rückfrage bestimmen | F20: Research | G20: 1 | H20: 3 | I20: =(G20+H20)/2 | J20: 2 | K20: F007, T-U004-03, F008 | M20: Offen | P20: Unterstützend | Q20: Kern | R20: features/chat | S20: Erlaubt
A21: T-U010-02 | B21: U010 | C21: M1 | D21: 18 | E21: Offene Rückfrage verwalten | F21: Code | G21: 2 | H21: 1 | I21: =(G21+H21)/2 | J21: 3 | K21: T-U010-01 | M21: Offen | P21: Nach menschlicher Freigabe | Q21: Kern | R21: features/chat | S21: Erlaubt
A22: T-U010-03 | B22: U010 | C22: M1 | D22: 19 | E22: Rückfrage im Chat verbinden | F22: Code | G22: 2 | H22: 1 | I22: =(G22+H22)/2 | J22: 3 | K22: T-U010-02 | M22: Offen | P22: Nach menschlicher Freigabe | Q22: Kern | R22: apps/web | S22: Erlaubt
A23: T-U026-01 | B23: U026 | C23: M1 | D23: 20 | E23: Ladezustand anzeigen | F23: Code | G23: 2 | H23: 1 | I23: =(G23+H23)/2 | J23: 3 | K23: F007 | L23: D03 | M23: Offen | P23: Nach menschlicher Freigabe | Q23: Kern | R23: apps/web | S23: Erlaubt
A24: T-U026-02 | B24: U026 | C24: M1 | D24: 21 | E24: Timeout und Abbruch umsetzen | F24: Code | G24: 2 | H24: 1 | I24: =(G24+H24)/2 | J24: 3 | K24: T-U026-01 | M24: Offen | P24: Nach menschlicher Freigabe | Q24: Kern | R24: apps/web | S24: Erlaubt
A25: T-U026-03 | B25: U026 | C25: M1 | D25: 22 | E25: Wiederholen ohne Duplikat anbieten | F25: Code | G25: 2 | H25: 1 | I25: =(G25+H25)/2 | J25: 3 | K25: T-U026-02 | M25: Offen | P25: Nach menschlicher Freigabe | Q25: Kern | R25: apps/web | S25: Erlaubt
A26: T-U027-01 | B26: U027 | C26: M1 | D26: 23 | E26: Einwilligungsablauf spezifizieren | F26: Research | G26: 1 | H26: 3 | I26: =(G26+H26)/2 | J26: 2 | K26: F003, F009 | L26: D05 | M26: Offen | P26: Unterstützend | Q26: Kern | R26: features/consent | S26: Erlaubt
A27: T-U027-02 | B27: U027 | C27: M1 | D27: 24 | E27: Zustimmung und Ablehnung anzeigen | F27: Code | G27: 2 | H27: 1 | I27: =(G27+H27)/2 | J27: 3 | K27: T-U027-01 | M27: Offen | P27: Nach menschlicher Freigabe | Q27: Kern | R27: apps/web | S27: Erlaubt
A28: T-U027-03 | B28: U027 | C28: M1 | D28: 25 | E28: Serverseitige Freigabe prüfen | F28: Test | G28: 2 | H28: 1 | I28: =(G28+H28)/2 | J28: 3 | K28: T-U027-02 | M28: Offen | P28: Unterstützend | Q28: Kern | R28: features/consent | S28: Erlaubt
A29: T-U027-04 | B29: U027 | C29: M1 | D29: 26 | E29: Widerruf mit laufender Anfrage behandeln | F29: Code | G29: 2 | H29: 1 | I29: =(G29+H29)/2 | J29: 3 | K29: T-U027-03 | M29: Offen | P29: Nach menschlicher Freigabe | Q29: Kern | R29: features/consent | S29: Erlaubt
A30: F010 | B30: BASIS | C30: M1 | D30: 27 | E30: Einwilligungsgeprüfte Modellroute verbinden | F30: Code | G30: 2 | H30: 1 | I30: =(G30+H30)/2 | J30: 3 | K30: F008, F009, T-U027-04 | M30: Offen | P30: Nach menschlicher Freigabe | Q30: Kern | R30: features/chat, security | S30: Erlaubt
A31: T-U028-01 | B31: U028 | C31: M1 | D31: 28 | E31: KI-Hinweis abstimmen | F31: Research | G31: 1 | H31: 3 | I31: =(G31+H31)/2 | J31: 2 | K31: F005, F009 | L31: D05 | M31: Offen | P31: Unterstützend | Q31: Kern | R31: knowledge | S31: Erlaubt
A32: T-U028-02 | B32: U028 | C32: M1 | D32: 29 | E32: Dauerhafte KI-Kennzeichnung einbauen | F32: Code | G32: 2 | H32: 1 | I32: =(G32+H32)/2 | J32: 3 | K32: T-U028-01 | M32: Offen | P32: Nach menschlicher Freigabe | Q32: Kern | R32: apps/web | S32: Erlaubt
A33: F015 | B33: BASIS | C33: M1 | D33: 30 | E33: M1-Abnahmelauf dokumentieren | F33: Test | G33: 2 | H33: 1 | I33: =(G33+H33)/2 | J33: 3 | K33: F010, F004, T-U004-03, T-U009-04, T-U010-03, T-U026-03, T-U028-02 | M33: Offen | P33: Unterstützend | Q33: Kern | R33: evals | S33: Erlaubt
A34: T-U017-01 | B34: U017 | C34: M1 | D34: 31 | E34: Deutsch-Englisch-Textkatalog erstellen | F34: Code | G34: 2 | H34: 1 | I34: =(G34+H34)/2 | J34: 3 | K34: F007, T-U009-04, T-U010-03, T-U026-03, T-U028-02 | L34: D07 | M34: Offen | P34: Nach menschlicher Freigabe | Q34: Kern | R34: apps/web | S34: Erlaubt | T34: Entscheidung DE/EN 14.10.2026
A35: T-U017-02 | B35: U017 | C35: M1 | D35: 32 | E35: Sprachwahl durchgängig übergeben | F35: Code | G35: 2 | H35: 1 | I35: =(G35+H35)/2 | J35: 3 | K35: T-U017-01 | M35: Offen | P35: Nach menschlicher Freigabe | Q35: Kern | R35: apps/web | S35: Erlaubt | T35: Entscheidung DE/EN 14.10.2026
A36: T-U017-03 | B36: U017 | C36: M1 | D36: 33 | E36: Zweisprachige Kernabläufe prüfen | F36: Test | G36: 2 | H36: 1 | I36: =(G36+H36)/2 | J36: 3 | K36: T-U017-02 | M36: Offen | P36: Unterstützend | Q36: Kern | R36: apps/web | S36: Erlaubt | T36: Entscheidung DE/EN 14.10.2026
A37: F011 | B37: BASIS | C37: M2 | D37: 34 | E37: Zwei Testkonten und Sitzungsidentität einrichten | F37: Code | G37: 2 | H37: 1 | I37: =(G37+H37)/2 | J37: 3 | K37: F007 | L37: D05 | M37: Offen | P37: Nach menschlicher Freigabe | Q37: Kern | R37: security | S37: Erlaubt
A38: F012 | B38: BASIS | C38: M2 | D38: 35 | E38: FHIR-Datenvertrag und Fixtures festlegen | F38: Research | G38: 1 | H38: 3 | I38: =(G38+H38)/2 | J38: 2 | K38: F009 | L38: D02 | M38: Offen | P38: Unterstützend | Q38: Kern | R38: contracts/fhir, data/synthetic | S38: Erlaubt
A39: F013 | B39: BASIS | C39: M2 | D39: 36 | E39: Speicherschnittstelle für eigene App-Daten bereitstellen | F39: Code | G39: 2 | H39: 1 | I39: =(G39+H39)/2 | J39: 3 | K39: F011 | L39: D06 | M39: Offen | P39: Nach menschlicher Freigabe | Q39: Kern | R39: adapters/db | S39: Erlaubt
A40: T-U005-01 | B40: U005 | C40: M2 | D40: 37 | E40: Berechtigungsmatrix definieren | F40: Research | G40: 1 | H40: 3 | I40: =(G40+H40)/2 | J40: 2 | K40: F007, F011, F012 | L40: D05 | M40: Offen | P40: Unterstützend | Q40: Kern | R40: security | S40: Erlaubt
...

Sheet Briefings
A1: Coding-Briefings nach Task-ID
A2: Gemeinsam mit der gleichnamigen Task-Zeile, ihrer User Story und den bestätigten Entscheidungen verwenden. Keine bestehende Codebasis oder Schnittstelle erfinden.
A3: Task-ID | B3: Konkreter Auftrag | C3: Eingabe / Ausgabe | D3: Abnahmekriterien | E3: Gezielte Prüfung | F3: Nicht enthalten | G3: Bestandsbezug
A4: F001 | B4: Lege UI-/Backend-Stack, Repositorystruktur, Modellbetrieb und Testwerkzeuge als kurze Teamentscheidung fest. | C4: Bestehendes Repository + Hardwareangaben → Entscheidungsnotiz. | D4: Entscheidung D01 und D03 haben bestätigten Stand; keine erfundenen Dateipfade. | E4: Startbefehle und Verantwortlichkeiten im Team nachvollzogen. | F4: Nur den beschriebenen Teil umsetzen. Keine neuen Features, keine echten Patientendaten, kein automatisches Training. Medizinische Regeln nicht selbst erfinden. Kein Projektboard oder Agenten-Worker in diesem Auftrag. Keine individuelle Bewertung, Diagnose oder Dringlichkeitseinstufung (D08). | G4: B001, B002
A5: F002 | B5: Ergänze minimale Projektstruktur, Konfigurationsbeispiel ohne Geheimnisse und Startanleitung für gewählten Stack. | C5: Bestätigter Stack → startbare leere Anwendung. | D5: Zweite Person kann Grundprojekt starten. | E5: Frischer Checkout ohne private Konfigurationsdatei. | F5: Nur den beschriebenen Teil umsetzen. Keine neuen Features, keine echten Patientendaten, kein automatisches Training. Medizinische Regeln nicht selbst erfinden. Kein Projektboard oder Agenten-Worker in diesem Auftrag. Keine individuelle Bewertung, Diagnose oder Dringlichkeitseinstufung (D08). | G5: B007
A6: F003 | B6: Definiere Nachricht, Chat-ID, Request-ID, Sprache, Antwort, Quellen und einheitliche Fehlercodes. | C6: UI-Nachricht → dokumentierter API-Vertrag. | D6: Beispielrequest und Beispielantwort sind schemavalid; maximale Eingabelänge ist festgelegt. | E6: Leerer Text und überlange Eingabe sind beschrieben. | F6: Nur den beschriebenen Teil umsetzen. Keine neuen Features, keine echten Patientendaten, kein automatisches Training. Medizinische Regeln nicht selbst erfinden. Kein Projektboard oder Agenten-Worker in diesem Auftrag. Keine individuelle Bewertung, Diagnose oder Dringlichkeitseinstufung (D08). | G6: B001, E003
A7: F004 | B7: Richte einen schnellen Testbefehl und automatischen Lauf für Pull Requests ein. Verwende nur synthetische Fixtures. | C7: Repository → automatischer Prüflauf. | D7: Fehlender Test lässt Prüflauf scheitern; erfolgreicher Lauf ist reproduzierbar. | E7: Absichtlich fehlschlagender Test in temporärem Branch. | F7: Nur den beschriebenen Teil umsetzen. Keine neuen Features, keine echten Patientendaten, kein automatisches Training. Medizinische Regeln nicht selbst erfinden. Kein Projektboard oder Agenten-Worker in diesem Auftrag. Keine individuelle Bewertung, Diagnose oder Dringlichkeitseinstufung (D08). | G7: B005, B006
A8: F005 | B8: Beschreibe Chatstart, Einwilligung, Eingabe, Antwort, Rückfrage, Laden und Fehler mit kleinen Screens. | C8: API-Vertrag → abgestimmte Skizzen. | D8: Ablauf auf Desktop und Smartphone durchspielbar. | E8: Team spielt Erfolgs- und Fehlerfall durch. | F8: Nur den beschriebenen Teil umsetzen. Keine neuen Features, keine echten Patientendaten, kein automatisches Training. Medizinische Regeln nicht selbst erfinden. Kein Projektboard oder Agenten-Worker in diesem Auftrag. Keine individuelle Bewertung, Diagnose oder Dringlichkeitseinstufung (D08). | G8: E001
A9: F006 | B9: Implementiere Eingabefeld, Senden und Nachrichtenliste zunächst mit lokalem Mock. | C9: Nachricht → lokaler Chatverlauf. | D9: Nachricht und feste Antwort erscheinen; leere Eingabe ist gesperrt. | E9: Tastatur, Doppelklick und lange Eingabe. | F9: Nur den beschriebenen Teil umsetzen. Keine neuen Features, keine echten Patientendaten, kein automatisches Training. Medizinische Regeln nicht selbst erfinden. Kein Projektboard oder Agenten-Worker in diesem Auftrag. Keine individuelle Bewertung, Diagnose oder Dringlichkeitseinstufung (D08). | G9: E002
A10: F007 | B10: Implementiere genau den Chat-Endpunkt aus F003 und verbinde ihn mit F006. | C10: Chatrequest → feste Chatantwort. | D10: Nachricht durchläuft UI und Server; ungültige Eingabe liefert vereinbarten Fehler. | E10: HTTP-Erfolg, Validierungsfehler und Verbindungsabbruch. | F10: Nur den beschriebenen Teil umsetzen. Keine neuen Features, keine echten Patientendaten, kein automatisches Training. Medizinische Regeln nicht selbst erfinden. Kein Projektboard oder Agenten-Worker in diesem Auftrag. Keine individuelle Bewertung, Diagnose oder Dringlichkeitseinstufung (D08). | G10: E003
A11: F008 | B11: Implementiere einen austauschbaren Modelladapter mit Fake für Tests, begrenzter Ausgabe und konfigurierbarem Timeout. | C11: Modellrequest → Rohantwort oder technischer Fehler. | D11: Adapter lässt sich ohne reales Modell testen; Modellkennung steht in Konfiguration. | E11: Fake-Erfolg, Timeout und nicht erreichbares Modell. | F11: Nur den beschriebenen Teil umsetzen. Keine neuen Features, keine echten Patientendaten, kein automatisches Training. Medizinische Regeln nicht selbst erfinden. Kein Projektboard oder Agenten-Worker in diesem Auftrag. Keine individuelle Bewertung, Diagnose oder Dringlichkeitseinstufung (D08). | G11: B002, B007
A12: F009 | B12: Definiere synthetische Eingaben und erlaubte technische Logfelder; Gesundheitsinhalte und Geheimnisse nicht standardmäßig loggen. | C12: Datenfluss → Testdaten-/Logging-Regel. | D12: Datenfluss und Logfelder sind abgestimmt. | E12: Synthetischer Geheimniswert darf nicht in Logs erscheinen. | F12: Nur den beschriebenen Teil umsetzen. Keine neuen Features, keine echten Patientendaten, kein automatisches Training. Medizinische Regeln nicht selbst erfinden. Kein Projektboard oder Agenten-Worker in diesem Auftrag. Keine individuelle Bewertung, Diagnose oder Dringlichkeitseinstufung (D08). | G12: B003, B004
A13: T-U004-01 | B13: Lege zwölf synthetische Beispiele mit Soll-Intent an: Gesundheit, fachfremd und unklar. Begrenze den MVP auf diese drei Klassen. | C13: Eingabe: einzelne deutsche Nachricht. Ausgabe: versionierte Fixture-Datei. | D13: Jeder Fall besitzt ID, Text und erwartete Klasse; Grenzfälle sind begründet. | E13: Enthält Mathefrage, Gesundheitsfrage und mehrdeutige Kurzfrage. | F13: Nur den beschriebenen Teil umsetzen. Keine neuen Features, keine echten Patientendaten, kein automatisches Training. Medizinische Regeln nicht selbst erfinden. Kein Projektboard oder Agenten-Worker in diesem Auftrag. Keine individuelle Bewertung, Diagnose oder Dringlichkeitseinstufung (D08). | G13: U004
A14: T-U004-02 | B14: Prüfe die Modellausgabe gegen das vereinbarte Intent-Schema. Ungültige Klassen und fehlende Felder führen zum definierten Fallback. | C14: Modelltext → validierter Intent oder kontrollierter Fehler. | D14: Nur vereinbarte Klassen passieren den Validator; fehlerhaftes JSON löst keine Folgeaktion aus. | E14: Ungültiges JSON, unbekannter Intent, leere Ausgabe. | F14: Nur den beschriebenen Teil umsetzen. Keine neuen Features, keine echten Patientendaten, kein automatisches Training. Medizinische Regeln nicht selbst erfinden. Kein Projektboard oder Agenten-Worker in diesem Auftrag. Keine individuelle Bewertung, Diagnose oder Dringlichkeitseinstufung (D08). | G14: U004
... A141: DOC-001 | B141: Siehe planning/work-orders/DOC-001.md. | C141: Befunde aus TEST-001 und Entscheidungen vom 14.10.2026 -> angepasste Regeln und Doku. | D141: Siehe Arbeitsauftrag. | E141: Strukturcheck im Gut- und Fehlerfall; Vertragsbeispiele inklusive Gegenprobe. | F141: Nur den beschriebenen Teil umsetzen. Keine echten personenbezogenen Daten. Keine individuelle Bewertung, Diagnose oder Dringlichkeitseinstufung (D08). Kein Produktcode. | G141: TEST-001, F002, F003

Sheet Entscheidungen
A1: Offene Entscheidungen vor der Umsetzung
A2: Vorschläge sind keine bereits getroffenen Architekturentscheidungen. Bestätigte Ergebnisse und Nachweislinks hier eintragen.
A3: ID | B3: Thema | C3: Zu klären | D3: Zuständigkeit | E3: Status | F3: Beschluss / Nachweis
A4: D01 | B4: Technischer Stack und Repository | C4: UI-/Backend-Sprache, Frameworks, Repositorystruktur, vorhandener Code und Startbefehle bestätigen. | D4: Architektur / Team | E4: Bestätigt | F4: Teamzustimmung Atakan 14.10.2026; docs/decisions/D01-Stack.md
A5: D02 | B5: FHIR und Messgrößen | C5: FHIR-Version, erlaubte Ressourcen, Profile, Einheiten, Zeitfilter und erste Messgröße bestätigen. | D5: Daten / Betreuung | E5: In Klärung | F5: Empfehlung (nicht bestätigt): docs/decisions/D02-FHIR.md
A6: D03 | B6: Modell und Laufzeit | C6: Modell, Lizenz, Zielhardware, Adaptervertrag, Ausgabe-/Zeitlimits und gemessene Latenz festlegen. | D6: LLM / Team | E6: In Klärung | F6: Empfehlung (nicht bestätigt): docs/decisions/D03-Modell.md
A7: D04 | B7: Fachliche Inhalte und Regeln | C7: Je Story kleinen Demo-Umfang, Quellen, Reviewperson und freigegebene Version dokumentieren. Keine pauschale Freigabe aller zukünftigen Regeln. | D7: Research / Fachbetreuung | E7: In Klärung | F7: Empfehlung (nicht bestätigt): docs/decisions/D04-Fachinhalte.md
A8: D05 | B8: Identität, Einwilligung und Datenfluss | C8: Demo-Anmeldung, Freigaben, Widerruf, Logdaten und Löschgrenzen mit Betreuung klären. | D8: Backend / Datenschutzkontakt | E8: In Klärung | F8: Empfehlung (nicht bestätigt): docs/decisions/D05-Identitaet-Einwilligung.md
A9: D06 | B9: Speicherung und Kontext | C9: Speichertechnik, Schema-/Migrationsablauf, Lebensdauer, Backups und Kontextlimit festlegen. | D9: Backend / Daten | E9: In Klärung | F9: Empfehlung (nicht bestätigt): docs/decisions/D06-Speicherung.md
A10: D07 | B10: Optionale Funktionen | C10: Englisch und weitere optionale Stories ausdrücklich auswählen. Aufgaben vorhanden bedeutet nicht MVP-Zusage. | D10: Koordination / Team | E10: In Klärung | F10: Empfehlung (nicht bestätigt): docs/decisions/D07-Optionaler-Umfang.md
A11: D08 | B11: Zweckbestimmung | C11: VitaSync ist kein Medizinprodukt: welche Funktionen sind erlaubt, welche ausgeschlossen. | D11: Projektleitung / Betreuung | E11: Bestätigt | F11: Vorgabe Projektleitung 14.10.2026; Details docs/decisions/D08-Zweckbestimmung.md. Formale Einschätzung durch Betreuung noch einholen.
A12: D09 | B12: Datenschutz und EU-Recht | C12: DSGVO-Pflichten, AI Act Art. 50 und Art. 4, TDDDG; Abgrenzung Hochrisiko-KI. | D12: Team / Betreuung / Datenschutzbeauftragter | E12: In Klärung | F12: Empfehlung (nicht bestätigt): docs/decisions/D09-Datenschutz-EU.md

Sheet DoD M1
A1: Definition of Done – Meilenstein 1
A2: Vorschlag aus dem bisherigen Backlog. Referenzen Bxxx/Exxx sind Ursprungs-IDs; Zuordnung siehe Briefings, Spalte Bestandsbezug.
A3: ID | B3: Bereich / Bezug | C3: Prüfbares Kriterium | D3: Nachweis | E3: Prüfverantwortung | F3: Status | G3: Nachweis / Link
A4: DOD1-01 | B4: UX / E001–E002 | C4: Auf Desktop und Smartphone lassen sich Nachricht eingeben, senden und Antwort/Verlauf lesen. Leere Eingaben werden abgefangen; Tastaturbedienung ist möglich. | D4: Live-Demo in zwei vereinbarten Bildschirmgrößen | E4: UI / UX | F4: Offen | G4: Probe/geplant: docs/nachweise/M1/DOD1-01.md
A5: DOD1-02 | B5: Integration / E003, B002, B007 | C5: UI → Backend → lokal betriebenes LLM → UI funktioniert auf der dokumentierten Zielhardware. Ein reines Mockup reicht zur M1-Abnahme nicht. | D5: End-to-End-Test und dokumentierter Startbefehl | E5: Backend / LLM | F5: Offen | G5: Probe/geplant: docs/nachweise/M1/DOD1-02.md
A6: DOD1-03 | B6: Anfrageerkennung / U004, U009 | C6: Gesundheitsfrage, fachfremde Frage und unklare Anfrage werden unterschieden. Validiertes Ausgabeformat und Fehler-Fallback funktionieren. Vorschlag: mindestens 18 von 20 vorher festgelegten Fällen korrekt. | D6: Versionierter Testdatensatz mit Soll- und Ist-Ergebnis | E6: Tests / LLM | F6: Offen | G6: Probe/geplant: docs/nachweise/M1/DOD1-03.md
A7: DOD1-04 | B7: Rückfragen / U010 | C7: Bei fehlenden Informationen wird gezielt nachgefragt. Eine Folgeantwort wird der offenen Rückfrage zugeordnet; kein kompletter Langzeitdialog als M1-Pflicht. | D7: Mindestens drei Dialogtests mit Folgeantwort | E7: Backend / Tests | F7: Offen | G7: Probe/geplant: docs/nachweise/M1/DOD1-04.md
A8: DOD1-05 | B8: Antwortqualität / U009 | C8: Eine allgemeine Gesundheitsfrage erhält eine relevante, kurze Antwort; Fachbegriffe werden erklärt. Quellen und Grenzen sind nachvollziehbar. Vorschlag: Erstantwort maximal 150 Wörter, Details auf Nachfrage. | D8: Review von fünf repräsentativen Antworten | E8: Research / Tests | F8: Offen | G8: Probe/geplant: docs/nachweise/M1/DOD1-05.md
A9: DOD1-06 | B9: Ladezustand / U026 | C9: Nach Senden erscheint innerhalb einer Sekunde ein Status. Nach konfigurierbarem Timeout (Startvorschlag 60 s) erscheinen Fehler und Wiederholen; keine doppelten Nachrichten. | D9: Erfolgs-, Timeout- und Verbindungsfehlertest; Laufzeitmessung | E9: UI / Backend | F9: Offen | G9: Probe/geplant: docs/nachweise/M1/DOD1-06.md
A10: DOD1-07 | B10: Chatfreigabe / U027 | C10: Vor Zustimmung gelangen Eingaben nicht zum Modell. Ablehnung verhindert Verarbeitung. Nach Widerruf werden neue Aufrufe blockiert; verspätete Antworten verworfen. Prüfen auch ohne UI-Sperre. | D10: Tests für Zustimmung, Ablehnung, Widerruf und direkten API-Aufruf | E10: Backend / Tests | F10: Offen | G10: Probe/geplant: docs/nachweise/M1/DOD1-07.md
A11: DOD1-08 | B11: KI-Transparenz / U028 | C11: Versionierter Hinweis wird vor Zustimmung angezeigt. KI-Kennzeichnung bleibt im Header sichtbar; Nutzer erkennen, dass keine ärztliche Diagnose erfolgt. | D11: Screenshots und manuelle Prüfung des Chatstarts | E11: UI / Research | F11: Offen | G11: Probe/geplant: docs/nachweise/M1/DOD1-08.md
A12: DOD1-09 | B12: M1-Grenzen / B001, B003 | C12: Demonstration nutzt ausschließlich synthetische Eingaben. M1 greift nicht auf echte Patientenakten zu; Gesundheitsinhalte werden nicht unbemerkt in Logs gespeichert. Keine Antwort enthält eine individuelle Bewertung, Diagnose oder Dringlichkeitseinstufung (D08). | D12: Abgestimmter Datenfluss und Prüfung von Logs/Testdaten | E12: Team / Research | F12: Offen | G12: Probe/geplant: docs/nachweise/M1/DOD1-09.md
A13: DOD1-10 | B13: Qualität / B005–B006 | C13: Relevante automatisierte Tests laufen erfolgreich. Kein bekannter Fehler blockiert Eingabe, Verarbeitung, Einwilligung oder Ausgabe. Änderungen wurden von einer zweiten Person geprüft. | D13: Testlauf, Review-Verweis und dokumentierte offene Fehler | E13: Tests / Review | F13: Offen | G13: Probe/geplant: docs/nachweise/M1/DOD1-10.md
A14: DOD1-11 | B14: Reproduzierbarkeit / Dokumentation | C14: Eine zweite Person kann die Version anhand der README starten. Modellversion, Hardware, Konfiguration, Einschränkungen und Entscheidungen sind dokumentiert. | D14: Startversuch durch zweites Teammitglied und Versionsstand | E14: Dokumentation | F14: Offen | G14: Probe/geplant: docs/nachweise/M1/DOD1-11.md
... A16: DOD1-13 | B16: Datenschutz / D09 | C16: Datenschutzhinweis wird vor der Einwilligung angezeigt und versioniert gespeichert. Verarbeitungsverzeichnis und TOM sind aktuell. Passwörter gehasht. KI-Antworten sind sichtbar und maschinenlesbar gekennzeichnet. | D16: Dokumente in docs/compliance, Tests für Hashing und Kennzeichnung | E16: Datenschutz / Security | F16: Offen | G16: Probe/geplant: docs/nachweise/M1/DOD1-13.md
